Workbook

Sheet 休日振替簿（入力用）
G1: 【 高 専 】 休 日 振 替 簿
A3: 副校長 | Q3: 担当者 | S3: 備考
E5: 月分 | H5: コース名 | J5: 職員番号 | M5: 氏名
A8: 従事日（曜日）及び従事時間 | D8: 管理用 | E8: 勤務 時間数 | G8: 振替期限（半日以上のみ） | I8: 振替日 | O8: 業務内容
G9: （下記②を参照ください）
A10: （うち休憩時間等） | I10: （全日・前半日・後半日いずれかを選択してください） | O10: （クラブ付添時はクラブ名まで記入）
C11: =IF(A11<>"",IF(COUNTIF(プルダウン用シート!A:A,'休日振替簿（入力用）'!A11)>0,"祝日",A11),"") | D11: =IF(A11="","",(WEEKDAY(A11,2))) | E11: =C13-A13-(C14-A14) -> 0 | G11: =IF(A11<>"",EDATE(A11,4)-1,"") | W11: =IFERROR(WEEKNUM($A11,16),"") -> 1 | X11: =IFERROR(WEEKNUM($A11,16),"") -> 1
W12: =IFERROR(WEEKNUM(I11,16),"") -> 1 | X12: =IFERROR(WEEKNUM(L11,16),"") -> 1
B13: ～ | I13: 前半日 | L13: 後半日
B14: ～ | H14: まで | O14: 場所 | R14: クラブ名 | S14: （ ）
C15: =IF(A15<>"",IF(COUNTIF(プルダウン用シート!A:A,'休日振替簿（入力用）'!A15)>0,"祝日",A15),"") | D15: =IF(A15="","",(WEEKDAY(A15,2))) | E15: =C17-A17-(C18-A18) -> 0 | G15: =IF(A15<>"",EDATE(A15,4)-1,"") | W15: =IFERROR(WEEKNUM($A15,16),"") -> 1 | X15: =IFERROR(WEEKNUM($A15,16),"") -> 1
W16: =IFERROR(WEEKNUM(I15,16),"") -> 1 | X16: =IFERROR(WEEKNUM(L15,16),"") -> 1
B17: ～ | I17: 全日
B18: ～ | H18: まで | O18: 場所 | R18: クラブ名 | S18: （ ）
C19: =IF(A19<>"",IF(COUNTIF(プルダウン用シート!A:A,'休日振替簿（入力用）'!A19)>0,"祝日",A19),"") | D19: =IF(A19="","",(WEEKDAY(A19,2))) | E19: =C21-A21-(C22-A22) -> 0 | G19: =IF(A19<>"",EDATE(A19,4)-1,"") | W19: =IFERROR(WEEKNUM($A19,16),"") -> 1 | X19: =IFERROR(WEEKNUM($A19,16),"") -> 1
W20: =IFERROR(WEEKNUM(I19,16),"") -> 1 | X20: =IFERROR(WEEKNUM(L19,16),"") -> 1
B21: ～
B22: ～ | H22: まで | O22: 場所 | R22: クラブ名 | S22: （ ）
C23: =IF(A23<>"",IF(COUNTIF(プルダウン用シート!A:A,'休日振替簿（入力用）'!A23)>0,"祝日",A23),"") | D23: =IF(A23="","",(WEEKDAY(A23,2))) | E23: =C25-A25-(C26-A26) -> 0 | G23: =IF(A23<>"",EDATE(A23,4)-1,"") | W23: =IFERROR(WEEKNUM($A23,16),"") -> 1 | X23: =IFERROR(WEEKNUM($A23,16),"") -> 1
W24: =IFERROR(WEEKNUM(I23,16),"") -> 1 | X24: =IFERROR(WEEKNUM(L23,16),"") -> 1
B25: ～
B26: ～ | H26: まで | O26: 場所 | R26: クラブ名 | S26: （ ）
C27: =IF(A27<>"",IF(COUNTIF(プルダウン用シート!A:A,'休日振替簿（入力用）'!A27)>0,"祝日",A27),"") | D27: =IF(A27="","",(WEEKDAY(A27,2))) | E27: =C29-A29-(C30-A30) -> 0 | G27: =IF(A27<>"",EDATE(A27,4)-1,"") | W27: =IFERROR(WEEKNUM($A27,16),"") -> 1 | X27: =IFERROR(WEEKNUM($A27,16),"") -> 1
W28: =IFERROR(WEEKNUM(I27,16),"") -> 1 | X28: =IFERROR(WEEKNUM(L27,16),"") -> 1
B29: ～
B30: ～ | H30: まで | O30: 場所 | R30: クラブ名 | S30: （ ）
A32: 記入上の注意： | B32: ①．全日又は半日（4時間）に満たない勤務時間となった場合は、別途、時間単位年休を申請して下さい。
B33: ②．振替は勤務日の前後4ヶ月までに取得して下さい。
B34: ③．（うち休憩時間等）欄に記載する時間は、食事のための自由時間を含む。
B35: ④．勤務時間が6時間を超える場合は45分、8時間を超える場合は60分の休憩時間をとることが労働基準法で定められています。
B36: ⑤．「休憩は、労働時間の途中に与えなければならない」（法第34条第1項）とされ、「始業後すぐ」または「終業直前」に休憩を与えるのは違法と判断されます。ただし、休憩時間が一括か分割かは不問です。
Q40: ver | R40: 45839
A42: 管理用
A43: 1 | B43: 月曜日 | C43: （4ヶ月）
A44: 2 | B44: 火曜日 | C44: （4ヶ月）
A45: 3 | B45: 水曜日 | C45: （4ヶ月）
A46: 4 | B46: 木曜日 | C46: （4ヶ月）
A47: 5 | B47: 金曜日 | C47: （4ヶ月）
A48: 6 | B48: 土曜日 | C48: =7*16-1 -> 111
A49: 7 | B49: 日曜日 | C49: =7*16-1 -> 111

Sheet 休日振替簿（見本）
G1: 【 高 専 】 休 日 振 替 簿
A3: 副校長 | Q3: 担当者 | S3: 備考
C5: 7 | E5: 月分 | H5: コース名 | I5: LN | J5: 職員番号 | K5: 12345678 | M5: 氏名 | N5: 高専 太郎
A8: 従事日（曜日）及び従事時間 | D8: 管理用 | E8: 勤務 時間数 | G8: 振替期限（半日以上のみ） | I8: 振替日 | O8: 業務内容
G9: （下記②を参照ください）
A10: （うち休憩時間等） | I10: （全日・前半日・後半日いずれかを選択してください） | O10: （クラブ付添時はクラブ名まで記入）
A11: 45858 | C11: =IF(A11<>"",IF(COUNTIF(プルダウン用シート!A:A,'休日振替簿（見本）'!A11)>0,"祝日",A11),"") -> 45858 | D11: =IF(A11="","",(WEEKDAY(A11,2))) -> 7 | E11: =C13-A13-(C14-A14) -> 0.32291667 | G11: =IF(A11<>"",EDATE(A11,4)-1,"") -> 45980 | I11: 45862 | O11: クラブ付添のため | W11: =IFERROR(WEEKNUM($A11,16),"") -> 30 | X11: =IFERROR(WEEKNUM($A11,16),"") -> 30
W12: =IFERROR(WEEKNUM(I11,16),"") -> 30 | X12: =IFERROR(WEEKNUM(L11,16),"") -> 1
A13: 0.36458333 | B13: ～ | C13: 0.71875 | I13: 全日
A14: 0.5 | B14: ～ | C14: 0.53125 | H14: まで | O14: 場所 | P14: 学内 | R14: クラブ名 | S14: （ xxx部 ）
A15: 45859 | C15: =IF(A15<>"",IF(COUNTIF(プルダウン用シート!A:A,'休日振替簿（見本）'!A15)>0,"祝日",A15),"") -> 祝日 | D15: =IF(A15="","",(WEEKDAY(A15,2))) -> 1 | E15: =C17-A17-(C18-A18) -> 0.16666667 | G15: =IF(A15<>"",EDATE(A15,4)-1,"") -> 45981 | I15: 45876 | O15: xxx学会発表のため | W15: =IFERROR(WEEKNUM($A15,16),"") -> 30 | X15: =IFERROR(WEEKNUM($A15,16),"") -> 30
W16: =IFERROR(WEEKNUM(I15,16),"") -> 32 | X16: =IFERROR(WEEKNUM(L15,16),"") -> 1
A17: 0.54166667 | B17: ～ | C17: 0.70833333 | I17: 前半日
B18: ～ | H18: まで | O18: 場所 | P18: 学内 | R18: クラブ名 | S18: （ ）
A19: 45865 | C19: =IF(A19<>"",IF(COUNTIF(プルダウン用シート!A:A,'休日振替簿（見本）'!A19)>0,"祝日",A19),"") -> 45865 | D19: =IF(A19="","",(WEEKDAY(A19,2))) -> 7 | E19: =C21-A21-(C22-A22) -> 0.16666667 | G19: =IF(A19<>"",EDATE(A19,4)-1,"") -> 45987 | I19: 45882 | O19: クラブ付添（大会）のため | W19: =IFERROR(WEEKNUM($A19,16),"") -> 31 | X19: =IFERROR(WEEKNUM($A19,16),"") -> 31
W20: =IFERROR(WEEKNUM(I19,16),"") -> 33 | X20: =IFERROR(WEEKNUM(L19,16),"") -> 1
A21: 0.36458333 | B21: ～ | C21: 0.5625 | I21: 後半日
A22: 0.5 | B22: ～ | C22: 0.53125 | H22: まで | O22: 場所 | P22: 学内 | R22: クラブ名 | S22: （ xxx部 ）
C23: =IF(A23<>"",IF(COUNTIF(プルダウン用シート!A:A,'休日振替簿（見本）'!A23)>0,"祝日",A23),"") | D23: =IF(A23="","",(WEEKDAY(A23,2))) | E23: =C25-A25-(C26-A26) -> 0 | G23: =IF(A23<>"",EDATE(A23,4)-1,"") | W23: =IFERROR(WEEKNUM($A23,16),"") -> 1 | X23: =IFERROR(WEEKNUM($A23,16),"") -> 1
W24: =IFERROR(WEEKNUM(I23,16),"") -> 1 | X24: =IFERROR(WEEKNUM(L23,16),"") -> 1
B25: ～
B26: ～ | H26: まで | O26: 場所 | R26: クラブ名 | S26: （ ）
C27: =IF(A27<>"",IF(COUNTIF(プルダウン用シート!A:A,'休日振替簿（見本）'!A27)>0,"祝日",A27),"") | D27: =IF(A27="","",(WEEKDAY(A27,2))) | E27: =C29-A29-(C30-A30) -> 0 | G27: =IF(A27<>"",EDATE(A27,4)-1,"") | W27: =IFERROR(WEEKNUM($A27,16),"") -> 1 | X27: =IFERROR(WEEKNUM($A27,16),"") -> 1
W28: =IFERROR(WEEKNUM(I27,16),"") -> 1 | X28: =IFERROR(WEEKNUM(L27,16),"") -> 1
B29: ～
B30: ～ | H30: まで | O30: 場所 | R30: クラブ名 | S30: （ ）
A32: 記入上の注意： | B32: ①．全日又は半日（4時間）に満たない勤務時間となった場合は、別途、時間単位年休を申請して下さい。
B33: ②．振替は勤務日の前後4ヶ月までに取得して下さい。
B34: ③．（うち休憩時間等）欄に記載する時間は、食事のための自由時間を含む。
B35: ④．勤務時間が6時間を超える場合は45分、8時間を超える場合は60分の休憩時間をとることが労働基準法で定められています。
B36: ⑤．「休憩は、労働時間の途中に与えなければならない」（法第34条第1項）とされ、「始業後すぐ」または「終業直前」に休憩を与えるのは違法と判断されます。ただし、休憩時間が一括か分割かは不問です。
Q40: ver | R40: 45839
A42: 管理用
A43: 1 | B43: 月曜日 | C43: （4ヶ月）
A44: 2 | B44: 火曜日 | C44: （4ヶ月）
A45: 3 | B45: 水曜日 | C45: （4ヶ月）
A46: 4 | B46: 木曜日 | C46: （4ヶ月）
A47: 5 | B47: 金曜日 | C47: （4ヶ月）
A48: 6 | B48: 土曜日 | C48: =7*16-1 -> 111
A49: 7 | B49: 日曜日 | C49: =7*16-1 -> 111

Sheet 休日振替簿（手書き用）_PDF化
G1: 【 高 専 】 休 日 振 替 簿
A3: 副校長 | Q3: 担当者 | S3: 備考
E5: 月分 | H5: コース名 | J5: 職員番号 | M5: 氏名
A8: 従事日（曜日）及び従事時間 | D8: 管理用 | E8: 勤務 時間数 | G8: 振替期限（半日以上のみ） | I8: 振替日 | O8: 業務内容
G9: （下記②を参照ください）
A10: （うち休憩時間等） | I10: （全日・前半日・後半日いずれかを選択してください） | O10: （クラブ付添時はクラブ名まで記入）
A11: 令和 年 月 日 （ ） | D11: =IF(A11="","",(WEEKDAY(A11,2))) -> #VALUE! | E11: □ 半日 □ 全日 | G11: 令和 年 月 日（ ） | I11: 令和 年 月 日（ ） | L11: 令和 年 月 日（ ） | W11: =IFERROR(WEEKNUM($A11,16),"") | X11: =IFERROR(WEEKNUM($A11,16),"")
W12: =IFERROR(WEEKNUM(I11,16),"") | X12: =IFERROR(WEEKNUM(L11,16),"")
A13: 時 分 ～ 時 分 | I13: （ 全日 ・ 前半日 ・ 後半日 ） | L13: （ 全日 ・ 前半日 ・ 後半日 ）
A14: （ 時 分 ～ 時 分 ） | H14: まで | O14: 場所 | P14: （ 学内 ・ 学外 ） | R14: クラブ名 | S14: （ ）
A15: 令和 年 月 日 （ ） | D15: =IF(A15="","",(WEEKDAY(A15,2))) -> #VALUE! | E15: □ 半日 □ 全日 | G15: 令和 年 月 日（ ） | I15: 令和 年 月 日（ ） | L15: 令和 年 月 日（ ） | W15: =IFERROR(WEEKNUM($A15,16),"") | X15: =IFERROR(WEEKNUM($A15,16),"")
W16: =IFERROR(WEEKNUM(I15,16),"") | X16: =IFERROR(WEEKNUM(L15,16),"")
A17: 時 分 ～ 時 分 | I17: （ 全日 ・ 前半日 ・ 後半日 ） | L17: （ 全日 ・ 前半日 ・ 後半日 ）
A18: （ 時 分 ～ 時 分 ） | H18: まで | O18: 場所 | P18: （ 学内 ・ 学外 ） | R18: クラブ名 | S18: （ ）
A19: 令和 年 月 日 （ ） | D19: =IF(A19="","",(WEEKDAY(A19,2))) -> #VALUE! | E19: □ 半日 □ 全日 | G19: 令和 年 月 日（ ） | I19: 令和 年 月 日（ ） | L19: 令和 年 月 日（ ） | W19: =IFERROR(WEEKNUM($A19,16),"") | X19: =IFERROR(WEEKNUM($A19,16),"")
W20: =IFERROR(WEEKNUM(I19,16),"") | X20: =IFERROR(WEEKNUM(L19,16),"")
A21: 時 分 ～ 時 分 | I21: （ 全日 ・ 前半日 ・ 後半日 ） | L21: （ 全日 ・ 前半日 ・ 後半日 ）
A22: （ 時 分 ～ 時 分 ） | H22: まで | O22: 場所 | P22: （ 学内 ・ 学外 ） | R22: クラブ名 | S22: （ ）
A23: 令和 年 月 日 （ ） | D23: =IF(A23="","",(WEEKDAY(A23,2))) -> #VALUE! | E23: □ 半日 □ 全日 | G23: 令和 年 月 日（ ） | I23: 令和 年 月 日（ ） | L23: 令和 年 月 日（ ） | W23: =IFERROR(WEEKNUM($A23,16),"") | X23: =IFERROR(WEEKNUM($A23,16),"")
W24: =IFERROR(WEEKNUM(I23,16),"") | X24: =IFERROR(WEEKNUM(L23,16),"")
A25: 時 分 ～ 時 分 | I25: （ 全日 ・ 前半日 ・ 後半日 ） | L25: （ 全日 ・ 前半日 ・ 後半日 ）
A26: （ 時 分 ～ 時 分 ） | H26: まで | O26: 場所 | P26: （ 学内 ・ 学外 ） | R26: クラブ名 | S26: （ ）
A27: 令和 年 月 日 （ ） | D27: =IF(A27="","",(WEEKDAY(A27,2))) -> #VALUE! | E27: □ 半日 □ 全日 | G27: 令和 年 月 日（ ） | I27: 令和 年 月 日（ ） | L27: 令和 年 月 日（ ） | W27: =IFERROR(WEEKNUM($A27,16),"") | X27: =IFERROR(WEEKNUM($A27,16),"")
W28: =IFERROR(WEEKNUM(I27,16),"") | X28: =IFERROR(WEEKNUM(L27,16),"")
A29: 時 分 ～ 時 分 | I29: （ 全日 ・ 前半日 ・ 後半日 ） | L29: （ 全日 ・ 前半日 ・ 後半日 ）
A30: （ 時 分 ～ 時 分 ） | H30: まで | O30: 場所 | P30: （ 学内 ・ 学外 ） | R30: クラブ名 | S30: （ ）
A32: 記入上の注意： | B32: ①．全日又は半日（4時間）に満たない勤務時間となった場合は、別途、時間単位年休を申請して下さい。
B33: ②．振替は勤務日の前後4ヶ月までに取得して下さい。
B34: ③．（うち休憩時間等）欄に記載する時間は、食事のための自由時間を含む。
B35: ④．勤務時間が6時間を超える場合は45分、8時間を超える場合は60分の休憩時間をとることが労働基準法で定められています。
B36: ⑤．「休憩は、労働時間の途中に与えなければならない」（法第34条第1項）とされ、「始業後すぐ」または「終業直前」に休憩を与えるのは違法と判断されます。ただし、休憩時間が一括か分割かは不問です。
Q40: ver | R40: 45839
A42: 管理用
A43: 1 | B43: 月曜日 | C43: （4ヶ月）
A44: 2 | B44: 火曜日 | C44: （4ヶ月）
A45: 3 | B45: 水曜日 | C45: （4ヶ月）
A46: 4 | B46: 木曜日 | C46: （4ヶ月）
A47: 5 | B47: 金曜日 | C47: （4ヶ月）
A48: 6 | B48: 土曜日 | C48: =7*16-1 -> 111
A49: 7 | B49: 日曜日 | C49: =7*16-1 -> 111

Sheet プルダウン用シート
F1: 勤務時間帯
A2: 祝日・年末年始休暇・行事予定 | F2: A勤 | G2: 0.33333333 | H2: 0.6875 | I2: 0.69791667
A3: 45411 | B3: 昭和の日 | C3: 2024年度 | F3: B勤 | G3: 0.36458333 | H3: 0.71875 | I3: 0.72916667
A4: 45415 | B4: 憲法記念日 | F4: C勤 | G4: 0.39583333 | H4: 0.75 | I4: 0.76041667
A5: 45416 | B5: みどりの日 | F5: D勤 | G5: 0.4375 | H5: 0.79166667 | I5: 0.80208333
A6: 45417 | B6: こどもの日 | F6: E勤 | G6: 0.47916667 | H6: 0.83333333 | I6: 0.84375
A7: 45418 | B7: 休日
A8: 45488 | B8: 海の日
A9: 45515 | B9: 山の日 | F9: 休日
A10: 45516 | B10: 休日
A11: 45551 | B11: 敬老の日
A12: 45557 | B12: 秋分の日 | F12: 曜日
A13: 45558 | B13: 休日 | F13: 土
A14: 45579 | B14: スポーツの日 | F14: 日
A15: 45599 | B15: 文化の日
A16: 45600 | B16: 休日 | F16: 差の理由
A17: 45619 | B17: 勤労感謝の日 | F17: 個人的事情で滞留
A18: 45658 | B18: 元日 | F18: 別途、時間外勤務申請
A19: 45659 | B19: 年末年始休暇 | F19: その他（備考に記載）
A20: 45660 | B20: 年末年始休暇
A21: 45670 | B21: 成人の日
A22: 45699 | B22: 建国記念の日
A23: 45711 | B23: 天皇誕生日
A24: 45712 | B24: 休日
A25: 45736 | B25: 春分の日
A26: 45776 | B26: 昭和の日 | C26: 2025年度
A27: 45780 | B27: 憲法記念日
A28: 45781 | B28: みどりの日
A29: 45782 | B29: こどもの日
A30: 45783 | B30: 休日
A31: 45859 | B31: 海の日
A32: 45880 | B32: 山の日
A33: 45915 | B33: 敬老の日
A34: 45923 | B34: 秋分の日
A35: 45943 | B35: スポーツの日
A36: 45964 | B36: 文化の日
A37: 45984 | B37: 勤労感謝の日
A38: 45985 | B38: 休日
... A43: 46101 | B43: 春分の日
A44: 46141 | B44: 昭和の日 | C44: 2026年度
...
