Workbook

Sheet 旅行命令上申書（近距離・国内旅行
A1: 教 職 員 | F1: 国内旅行 | U1: 旅 行 命 令 上 申 書 | AR1: 旅行命令権者 | AX1: 確認欄 | AY1: 課長 | BC1: 課長代理 | BG1: 係長 | BK1: 係員
A6: 公立大学法人大阪 理事長 様 | BE6: 月 日
A8: 所 属 | G8: 大阪公立大学工業高等専門学校 | AH8: 旅行者氏名
G9: （役 職） | N9: (選択してください)
B11: 次のとおり旅行命令されるよう上申します。
A13: 旅行期間 | P13: から | AA13: まで | AF13: 日間
A15: 出 発 地 | P15: 最寄駅又は バス停※1 | AF15: 線
AF16: 駅
A17: 帰 着 地 | P17: 最寄駅又は バス停※1 | AF17: 線
AF18: 駅
B20: 年月日※2 | G20: 用務先名称 | T20: 用務先住所 | AE20: 最寄駅又は バス停※1 | AL20: 宿泊先名称 | AX20: 用務内容詳細
A22: 1 | AK22: 線
AK23: 駅 | AL23: 用務時刻※3 | AQ23: : | AT23: ～ | AU23: :
A24: 2 | AK24: 線
AK25: 駅 | AL25: 用務時刻※3 | AQ25: ： | AT25: ～ | AU25: ：
A26: 3 | AK26: 線
AK27: 駅 | AL27: 用務時刻※3 | AQ27: ： | AT27: ～ | AU27: ：
A28: 4 | AK28: 線
AK29: 駅 | AL29: 用務時刻※3 | AQ29: ： | AT29: ～ | AU29: ：
A30: 5 | AK30: 線
AK31: 駅 | AL31: 用務時刻※3 | AQ31: ： | AT31: ～ | AU31: ：
A33: 通勤定期区間 ※1 | G33: ① | O33: ～ | W33: ( | AD33: ) | AE33: ③ | AM33: ～ | AU33: ( | BB33: ) | BC33: □ | BE33: 定期券なし
G34: ② | O34: ～ | W34: ( | AD34: ) | AE34: ④ | AM34: ～ | AU34: ( | BB34: ) | BC34: ※①が自宅側となるように記入
BC35: 裏面も記入してください。
A37: 教 職 員 | F37: 国内旅行
A40: 財 源 | G40: 財源名称 | O40: (選択してください)
G41: =IF(OR(O40="基盤研究費",O40="自己負担（精算なし）",O40=""),"",IF(O40="大学運営経費","予算名称",IF(COUNTIF(O40,"*科研費*"),"種目",IF(O40="先方負担","負担種別（全額/一部）",IF(O40="その他","詳細","資金(ﾌﾟﾛｼﾞｪｸﾄ)名称"))))) -> 資金(ﾌﾟﾛｼﾞｪｸﾄ)名称
G42: =+IF(OR(O40="基盤研究費",O40="大学運営経費",O40="自己負担（精算なし）",O40="その他",O40=""),"",IF(O40="先方負担","先方負担先名",IF(COUNTIF(O40,"*科研費*"),"研究代表者名","経費区分（直接/間接）"))) -> 経費区分（直接/間接）
G43: =+IF(OR(O40="基盤研究費",O40="大学運営経費",O40="自己負担（精算なし）",O40="その他",O40=""),"",IF(O40="先方負担","先方負担内容",IF(COUNTIF(O40,"*科研費*"),"所管（ﾌﾟﾛｼﾞｪｸﾄ）名称","ﾌﾟﾛｼﾞｪｸﾄNo.(ｺｰﾄﾞ)"))) -> ﾌﾟﾛｼﾞｪｸﾄNo.(ｺｰﾄﾞ)
G44: =IF(COUNTIF(O40,"*科研費*"),"ﾌﾟﾛｼﾞｪｸﾄNo.(ｺｰﾄﾞ)","")
G45: 備考
A46: 法人カード | G46: □ | I46: 利用予定あり | O46: □ | Q46: 利用予定なし
G47: □ | I47: 航空機料金 | O47: □ | Q47: 鉄道料金 | W47: □ | Y47: その他交通費( )
G48: □ | I48: 宿泊料 | O48: □ | Q48: 参加費 | W48: □ | Y48: その他( )
A49: 参 加 費 | G49: □ | I49: 参加費の精算を希望する
A51: 仮 払 申 請 | G51: □ | I51: 仮払を希望する※4
A53: 備 考※5
A58: ◆記入に関する注意事項
A60: ※1 最寄駅及び定期区間は「鉄道会社／駅名」又は「バス会社／バス停名」を記入してください。
A61: ※2 旅行期間中の休日に業務を行う場合は、休日振替又は超過勤務の手続きが必要です。
...

Sheet 旅行報告書兼精算依頼書（国内旅行
A1: 教 職 員 | F1: 国内旅行 | R1: 旅 行 報 告 書 兼 精 算 依 頼 書 | AR1: 旅行命令権者 | AX1: 確認欄 | AY1: 課長 | BC1: 課長代理 | BG1: 係長 | BK1: 係員
A6: 公立大学法人大阪 理事長 様 | BE6: =INDEX(B22:B31,COUNTA(B22:B31))
A8: 所 属 | G8: =IF('旅行命令上申書（近距離・国内旅行'!G8:AG8="","",'旅行命令上申書（近距離・国内旅行'!G8:AG8) -> 大阪公立大学工業高等専門学校 | AH8: 旅行者氏名 | AN8: =IF('旅行命令上申書（近距離・国内旅行'!AN8:BN9="","",'旅行命令上申書（近距離・国内旅行'!AN8:BN9)
G9: （役 職） | N9: =IF('旅行命令上申書（近距離・国内旅行'!N9:AG9="","",'旅行命令上申書（近距離・国内旅行'!N9:AG9) -> (選択してください)
B11: 次のとおり旅行したことを報告し、旅費の精算を依頼します。
A13: 旅行期間 | G13: =IF('旅行命令上申書（近距離・国内旅行'!G13:O14="","",'旅行命令上申書（近距離・国内旅行'!G13:O14) | P13: から | R13: =IF('旅行命令上申書（近距離・国内旅行'!R13:Z14="","",'旅行命令上申書（近距離・国内旅行'!R13:Z14) | AA13: まで | AC13: =IF('旅行命令上申書（近距離・国内旅行'!AC13:AE14="","",'旅行命令上申書（近距離・国内旅行'!AC13:AE14) | AF13: 日間 | AH13: 上申書からの 変更内容※2 | AP13: 変更あり | AX13: 変更なし
A15: 出 発 地 | G15: =IF('旅行命令上申書（近距離・国内旅行'!G15:O16="","",'旅行命令上申書（近距離・国内旅行'!G15:O16) | P15: 最寄駅又は バス停※1 | V15: =IF('旅行命令上申書（近距離・国内旅行'!V15:AE15="","",'旅行命令上申書（近距離・国内旅行'!V15:AE15) | AF15: 線
V16: =IF('旅行命令上申書（近距離・国内旅行'!V16:AE16="","",'旅行命令上申書（近距離・国内旅行'!V16:AE16) | AF16: 駅
A17: 帰 着 地 | G17: =IF('旅行命令上申書（近距離・国内旅行'!G17:O18="","",'旅行命令上申書（近距離・国内旅行'!G17:O18) | P17: 最寄駅又は バス停※1 | V17: =IF('旅行命令上申書（近距離・国内旅行'!V17:AE17="","",'旅行命令上申書（近距離・国内旅行'!V17:AE17) | AF17: 線
V18: =IF('旅行命令上申書（近距離・国内旅行'!V18:AE18="","",'旅行命令上申書（近距離・国内旅行'!V18:AE18) | AF18: 駅
B20: 年月日※3 | G20: 用務先名称 | T20: 用務先住所 | AE20: 最寄駅又は バス停※1 | AL20: 宿泊先名称 | AX20: 用務実施内容（報告）
A22: 1 | B22: =IF('旅行命令上申書（近距離・国内旅行'!B22:F23="","",'旅行命令上申書（近距離・国内旅行'!B22:F23) | G22: =IF('旅行命令上申書（近距離・国内旅行'!G22:S23="","",'旅行命令上申書（近距離・国内旅行'!G22:S23) | T22: =IF('旅行命令上申書（近距離・国内旅行'!T22:AD23="","",'旅行命令上申書（近距離・国内旅行'!T22:AD23) | AE22: =IF('旅行命令上申書（近距離・国内旅行'!AE22:AJ22="","",'旅行命令上申書（近距離・国内旅行'!AE22:AJ22) | AK22: 線 | AL22: =IF('旅行命令上申書（近距離・国内旅行'!AL22:AW22="","",'旅行命令上申書（近距離・国内旅行'!AL22:AW22) | AX22: ='旅行命令上申書（近距離・国内旅行'!AX22&""
G23: 応接者等 | K23: （ | S23: ） | AE23: =IF('旅行命令上申書（近距離・国内旅行'!AE23:AJ23="","",'旅行命令上申書（近距離・国内旅行'!AE23:AJ23) | AK23: 駅 | AL23: 用務時刻※4 | AQ23: =IF('旅行命令上申書（近距離・国内旅行'!AQ23:AS23="","",'旅行命令上申書（近距離・国内旅行'!AQ23:AS23) -> : | AT23: ～ | AU23: =IF('旅行命令上申書（近距離・国内旅行'!AU23:AW23="","",'旅行命令上申書（近距離・国内旅行'!AU23:AW23) -> :
A24: 2 | B24: =IF('旅行命令上申書（近距離・国内旅行'!B24:F25="","",'旅行命令上申書（近距離・国内旅行'!B24:F25) | G24: =IF('旅行命令上申書（近距離・国内旅行'!G24:S25="","",'旅行命令上申書（近距離・国内旅行'!G24:S25) | T24: =IF('旅行命令上申書（近距離・国内旅行'!T24:AD25="","",'旅行命令上申書（近距離・国内旅行'!T24:AD25) | AE24: =IF('旅行命令上申書（近距離・国内旅行'!AE24:AJ24="","",'旅行命令上申書（近距離・国内旅行'!AE24:AJ24) | AK24: 線 | AL24: =IF('旅行命令上申書（近距離・国内旅行'!AL24:AW24="","",'旅行命令上申書（近距離・国内旅行'!AL24:AW24) | AX24: ='旅行命令上申書（近距離・国内旅行'!AX24&""
G25: 応接者等 | K25: （ | S25: ） | AE25: =IF('旅行命令上申書（近距離・国内旅行'!AE25:AJ25="","",'旅行命令上申書（近距離・国内旅行'!AE25:AJ25) | AK25: 駅 | AL25: 用務時刻※4 | AQ25: =IF('旅行命令上申書（近距離・国内旅行'!AQ25:AS25="","",'旅行命令上申書（近距離・国内旅行'!AQ25:AS25) -> ： | AT25: ～ | AU25: =IF('旅行命令上申書（近距離・国内旅行'!AU25:AW25="","",'旅行命令上申書（近距離・国内旅行'!AU25:AW25) -> ：
A26: 3 | B26: =IF('旅行命令上申書（近距離・国内旅行'!B26:F27="","",'旅行命令上申書（近距離・国内旅行'!B26:F27) | G26: =IF('旅行命令上申書（近距離・国内旅行'!G26:S27="","",'旅行命令上申書（近距離・国内旅行'!G26:S27) | T26: =IF('旅行命令上申書（近距離・国内旅行'!T26:AD27="","",'旅行命令上申書（近距離・国内旅行'!T26:AD27) | AE26: =IF('旅行命令上申書（近距離・国内旅行'!AE26:AJ26="","",'旅行命令上申書（近距離・国内旅行'!AE26:AJ26) | AK26: 線 | AL26: =IF('旅行命令上申書（近距離・国内旅行'!AL26:AW26="","",'旅行命令上申書（近距離・国内旅行'!AL26:AW26) | AX26: ='旅行命令上申書（近距離・国内旅行'!AX26&""
G27: 応接者等 | K27: （ | S27: ） | AE27: =IF('旅行命令上申書（近距離・国内旅行'!AE27:AJ27="","",'旅行命令上申書（近距離・国内旅行'!AE27:AJ27) | AK27: 駅 | AL27: 用務時刻※4 | AQ27: =IF('旅行命令上申書（近距離・国内旅行'!AQ27:AS27="","",'旅行命令上申書（近距離・国内旅行'!AQ27:AS27) -> ： | AT27: ～ | AU27: =IF('旅行命令上申書（近距離・国内旅行'!AU27:AW27="","",'旅行命令上申書（近距離・国内旅行'!AU27:AW27) -> ：
A28: 4 | B28: =IF('旅行命令上申書（近距離・国内旅行'!B28:F29="","",'旅行命令上申書（近距離・国内旅行'!B28:F29) | G28: =IF('旅行命令上申書（近距離・国内旅行'!G28:S29="","",'旅行命令上申書（近距離・国内旅行'!G28:S29) | T28: =IF('旅行命令上申書（近距離・国内旅行'!T28:AD29="","",'旅行命令上申書（近距離・国内旅行'!T28:AD29) | AE28: =IF('旅行命令上申書（近距離・国内旅行'!AE28:AJ28="","",'旅行命令上申書（近距離・国内旅行'!AE28:AJ28) | AK28: 線 | AL28: =IF('旅行命令上申書（近距離・国内旅行'!AL28:AW28="","",'旅行命令上申書（近距離・国内旅行'!AL28:AW28) | AX28: ='旅行命令上申書（近距離・国内旅行'!AX28&""
G29: 応接者等 | K29: （ | S29: ） | AE29: =IF('旅行命令上申書（近距離・国内旅行'!AE29:AJ29="","",'旅行命令上申書（近距離・国内旅行'!AE29:AJ29) | AK29: 駅 | AL29: 用務時刻※4 | AQ29: =IF('旅行命令上申書（近距離・国内旅行'!AQ29:AS29="","",'旅行命令上申書（近距離・国内旅行'!AQ29:AS29) -> ： | AT29: ～ | AU29: =IF('旅行命令上申書（近距離・国内旅行'!AU29:AW29="","",'旅行命令上申書（近距離・国内旅行'!AU29:AW29) -> ：
A30: 5 | B30: =IF('旅行命令上申書（近距離・国内旅行'!B30:F31="","",'旅行命令上申書（近距離・国内旅行'!B30:F31) | G30: =IF('旅行命令上申書（近距離・国内旅行'!G30:S31="","",'旅行命令上申書（近距離・国内旅行'!G30:S31) | T30: =IF('旅行命令上申書（近距離・国内旅行'!T30:AD31="","",'旅行命令上申書（近距離・国内旅行'!T30:AD31) | AE30: =IF('旅行命令上申書（近距離・国内旅行'!AE30:AJ30="","",'旅行命令上申書（近距離・国内旅行'!AE30:AJ30) | AK30: 線 | AL30: =IF('旅行命令上申書（近距離・国内旅行'!AL30:AW30="","",'旅行命令上申書（近距離・国内旅行'!AL30:AW30) | AX30: ='旅行命令上申書（近距離・国内旅行'!AX30&""
G31: 応接者等 | K31: （ | S31: ） | AE31: =IF('旅行命令上申書（近距離・国内旅行'!AE31:AJ31="","",'旅行命令上申書（近距離・国内旅行'!AE31:AJ31) | AK31: 駅 | AL31: 用務時刻※4 | AQ31: =IF('旅行命令上申書（近距離・国内旅行'!AQ31:AS31="","",'旅行命令上申書（近距離・国内旅行'!AQ31:AS31) -> ： | AT31: ～ | AU31: =IF('旅行命令上申書（近距離・国内旅行'!AU31:AW31="","",'旅行命令上申書（近距離・国内旅行'!AU31:AW31) -> ：
A33: 通勤定期区間 ※1 | G33: ① | H33: =IF('旅行命令上申書（近距離・国内旅行'!H33:N33="","",'旅行命令上申書（近距離・国内旅行'!H33:N33) | O33: ～ | P33: =IF('旅行命令上申書（近距離・国内旅行'!P33:V33="","",'旅行命令上申書（近距離・国内旅行'!P33:V33) | W33: ( | X33: =IF('旅行命令上申書（近距離・国内旅行'!X33:AC33="","",'旅行命令上申書（近距離・国内旅行'!X33:AC33) | AD33: ) | AE33: ③ | AF33: =IF('旅行命令上申書（近距離・国内旅行'!AF33:AL33="","",'旅行命令上申書（近距離・国内旅行'!AF33:AL33) | AM33: ～ | AN33: =IF('旅行命令上申書（近距離・国内旅行'!AN33:AT33="","",'旅行命令上申書（近距離・国内旅行'!AN33:AT33) | AU33: ( | AV33: =IF('旅行命令上申書（近距離・国内旅行'!AV33:BA33="","",'旅行命令上申書（近距離・国内旅行'!AV33:BA33) | BB33: ) | BC33: ='旅行命令上申書（近距離・国内旅行'!BC33:BD33 -> □ | BE33: 定期券なし
G34: ② | H34: =IF('旅行命令上申書（近距離・国内旅行'!H34:N34="","",'旅行命令上申書（近距離・国内旅行'!H34:N34) | O34: ～ | P34: =IF('旅行命令上申書（近距離・国内旅行'!P34:V34="","",'旅行命令上申書（近距離・国内旅行'!P34:V34) | W34: ( | X34: =IF('旅行命令上申書（近距離・国内旅行'!X34:AC34="","",'旅行命令上申書（近距離・国内旅行'!X34:AC34) | AD34: ) | AE34: ④ | AF34: =IF('旅行命令上申書（近距離・国内旅行'!AF34:AL34="","",'旅行命令上申書（近距離・国内旅行'!AF34:AL34) | AM34: ～ | AN34: =IF('旅行命令上申書（近距離・国内旅行'!AN34:AT34="","",'旅行命令上申書（近距離・国内旅行'!AN34:AT34) | AU34: ( | AV34: =IF('旅行命令上申書（近距離・国内旅行'!AV34:BA34="","",'旅行命令上申書（近距離・国内旅行'!AV34:BA34) | BB34: ) | BC34: ※①が自宅側となるように記入
BC35: 裏面も記入してください。
A37: 教 職 員 | F37: 国内旅行
A40: 財 源 | G40: 財源名称 | O40: =IF('旅行命令上申書（近距離・国内旅行'!O40:AG40="","",'旅行命令上申書（近距離・国内旅行'!O40:AG40) -> (選択してください)
G41: =IF(OR(O40="基盤研究費",O40="自己負担（精算なし）",O40=""),"",IF(O40="大学運営経費","予算名称",IF(COUNTIF(O40,"*科研費*"),"種目",IF(O40="先方負担","負担種別（全額/一部）",IF(O40="その他","詳細","資金(ﾌﾟﾛｼﾞｪｸﾄ)名称"))))) -> 資金(ﾌﾟﾛｼﾞｪｸﾄ)名称 | O41: =IF('旅行命令上申書（近距離・国内旅行'!O41:AG41="","",'旅行命令上申書（近距離・国内旅行'!O41:AG41)
G42: =+IF(OR(O40="基盤研究費",O40="大学運営経費",O40="自己負担（精算なし）",O40="その他",O40=""),"",IF(O40="先方負担","先方負担先名",IF(COUNTIF(O40,"*科研費*"),"研究代表者名","経費区分（直接/間接）"))) -> 経費区分（直接/間接） | O42: =IF('旅行命令上申書（近距離・国内旅行'!O42:AG42="","",'旅行命令上申書（近距離・国内旅行'!O42:AG42)
G43: =+IF(OR(O40="基盤研究費",O40="大学運営経費",O40="自己負担（精算なし）",O40="その他",O40=""),"",IF(O40="先方負担","先方負担内容",IF(COUNTIF(O40,"*科研費*"),"所管（ﾌﾟﾛｼﾞｪｸﾄ）名称","ﾌﾟﾛｼﾞｪｸﾄNo.(ｺｰﾄﾞ)"))) -> ﾌﾟﾛｼﾞｪｸﾄNo.(ｺｰﾄﾞ) | O43: =IF('旅行命令上申書（近距離・国内旅行'!O43:AG43="","",'旅行命令上申書（近距離・国内旅行'!O43:AG43)
G44: =IF(COUNTIF(O40,"*科研費*"),"ﾌﾟﾛｼﾞｪｸﾄNo.(ｺｰﾄﾞ)","") | O44: =IF('旅行命令上申書（近距離・国内旅行'!O44:AG44="","",'旅行命令上申書（近距離・国内旅行'!O44:AG44)
G45: 備考 | O45: =IF('旅行命令上申書（近距離・国内旅行'!O45:AG45="","",'旅行命令上申書（近距離・国内旅行'!O45:AG45)
A46: 法人カード | G46: ='旅行命令上申書（近距離・国内旅行'!G46:H46 -> □ | I46: 利用あり | O46: ='旅行命令上申書（近距離・国内旅行'!O46:P46 -> □ | Q46: 利用なし
G47: ='旅行命令上申書（近距離・国内旅行'!G47:H47 -> □ | I47: 航空機料金 | O47: ='旅行命令上申書（近距離・国内旅行'!O47:P47 -> □ | Q47: 鉄道料金 | W47: ='旅行命令上申書（近距離・国内旅行'!W47:X47 -> □ | Y47: その他交通費( )
G48: ='旅行命令上申書（近距離・国内旅行'!G48:H48 -> □ | I48: 宿泊料 | O48: ='旅行命令上申書（近距離・国内旅行'!O48:P48 -> □ | Q48: 参加費 | W48: ='旅行命令上申書（近距離・国内旅行'!W48:X48 -> □ | Y48: その他( )
A49: 参 加 費 | G49: ='旅行命令上申書（近距離・国内旅行'!G49:H50 -> □ | I49: 参加費の精算を希望する
A51: 仮 払 精 算 ※5 | G51: □ | I51: 仮払申請額から変更がある（追給あり）
G52: □ | I52: 仮払申請額から変更がある（戻入あり）
A53: 備 考※6 | G53: =IF('旅行命令上申書（近距離・国内旅行'!G53:AG56="","",'旅行命令上申書（近距離・国内旅行'!G53:AG56)
A58: ◆記入に関する注意事項
A60: ※1 最寄駅及び定期区間は「鉄道会社／駅名」又は「バス会社／バス停名」を記入してください。
...

Sheet 記入例（国内旅行
A1: 教 職 員 | F1: 国内旅行 | U1: 旅行命令上申書（記入例） | AR1: 旅行命令権者 | AX1: 確認欄 | AY1: 課長 | BC1: 課長代理 | BG1: 係長 | BK1: 係員
A6: 公立大学法人大阪 理事長 様 | BE6: 年 月 日
A8: 所 属 | AH8: 旅行者氏名
G9: （役 職）
B11: 次のとおり旅行命令されるよう上申します。
A13: 旅行期間 | G13: 44389 | P13: から | R13: 44390 | AA13: まで | AC13: 2 | AF13: 日間
A15: 出 発 地 | G15: 杉本キャンパス | P15: 最寄駅又は バス停※1 | V15: ＪＲ | AF15: 線
V16: 杉本町 | AF16: 駅
A17: 帰 着 地 | G17: 自宅 | P17: 最寄駅又は バス停※1 | V17: 大阪メトロ | AF17: 線
V18: 昭和町 | AF18: 駅
B20: 年月日※2 | G20: 用務先名称 | T20: 用務先住所 | AE20: 最寄駅又は バス停※1 | AL20: 宿泊先名称 | AX20: 用務内容詳細
A22: 1 | B22: 44390 | G22: 東京○○センター | T22: 東京都渋谷区○○○○X-XX | AE22: ＪＲ | AK22: 線 | AL22: ○○ビジネスホテル | AX22: 研究課題である「○○」に関する情報収集と研究に関する打ち合わせを行った。
AE23: 新宿 | AK23: 駅 | AL23: 用務時刻※3 | AQ23: 0.375 | AT23: ～ | AU23: 0.70833333
A24: 2 | AK24: 線
AK25: 駅 | AL25: 用務時刻※3 | AQ25: ： | AT25: ～ | AU25: ：
A26: 3 | AK26: 線
AK27: 駅 | AL27: 用務時刻※3 | AQ27: ： | AT27: ～ | AU27: ：
A28: 4 | AK28: 線
AK29: 駅 | AL29: 用務時刻※3 | AQ29: ： | AT29: ～ | AU29: ：
A30: 5 | AK30: 線
AK31: 駅 | AL31: 用務時刻※3 | AQ31: ： | AT31: ～ | AU31: ：
A33: 通勤定期区間 ※1 | G33: ① | H33: （自宅最寄り駅） | O33: ～ | P33: （乗換駅） | W33: ( | X33: 大阪メトロ | AD33: ) | AE33: ③ | AM33: ～ | AU33: ( | BB33: ) | BE33: 定期券なし
G34: ② | H34: （乗換駅） | O34: ～ | P34: （勤務地最寄り駅） | W34: ( | X34: ＪＲ | AD34: ) | AE34: ④ | AM34: ～ | AU34: ( | BB34: ) | BC34: ※①が自宅側となるように記入
BC35: 裏面も記入してください。
A37: 教 職 員 | F37: 国内旅行
A40: 財 源 | G40: 財源名称 | O40: 大学運営経費
G41: =IF(OR(O40="基盤研究費",O40="自己負担（精算なし）",O40=""),"",IF(O40="大学運営経費","予算名称",IF(COUNTIF(O40,"*科研費*"),"種目",IF(O40="先方負担","負担種別（全額/一部）",IF(O40="その他","詳細","資金(ﾌﾟﾛｼﾞｪｸﾄ)名称"))))) -> 予算名称 | O41: ○○○○
G42: =+IF(OR(O40="基盤研究費",O40="大学運営経費",O40="自己負担（精算なし）",O40="その他",O40=""),"",IF(O40="先方負担","先方負担先名",IF(COUNTIF(O40,"*科研費*"),"研究代表者名","経費区分（直接/間接）")))
G43: =+IF(OR(O40="基盤研究費",O40="大学運営経費",O40="自己負担（精算なし）",O40="その他",O40=""),"",IF(O40="先方負担","先方負担内容",IF(COUNTIF(O40,"*科研費*"),"所管（ﾌﾟﾛｼﾞｪｸﾄ）名称","ﾌﾟﾛｼﾞｪｸﾄNo.(ｺｰﾄﾞ)")))
G44: =IF(COUNTIF(O40,"*科研費*"),"ﾌﾟﾛｼﾞｪｸﾄNo.(ｺｰﾄﾞ)","")
G45: 備考
A46: 法人カード | I46: 利用予定あり | Q46: 利用予定なし
I47: 航空機料金 | Q47: 鉄道料金 | Y47: その他交通費( )
I48: 宿泊料 | Q48: 参加費 | Y48: その他( )
A49: 参 加 費 | G49: 参加費の精算を希望する
A51: 仮 払 申 請 | G51: 仮払を希望する※4
A53: 備 考※5
A58: ◆記入に関する注意事項
A60: ※1 最寄駅及び定期区間は「鉄道会社／駅名」又は「バス会社／バス停名」を記入してください。
A61: ※2 旅行期間中の休日に業務を行う場合は、休日振替又は超過勤務の手続きが必要です。
...

Sheet 記入例旅行報告書兼精算依頼書（国内旅行
A1: 教 職 員 | F1: 国内旅行 | R1: 旅行報告書兼精算依頼書（記入例） | AR1: 旅行命令権者 | AX1: 確認欄 | AY1: 課長 | BC1: 課長代理 | BG1: 係長 | BK1: 係員
A6: 公立大学法人大阪 理事長 様 | BE6: 年 月 日
A8: 所 属 | AH8: 旅行者氏名
G9: （役 職）
B11: 次のとおり旅行したことを報告し、旅費の精算を依頼します。
A13: 旅行期間 | G13: 44389 | P13: から | R13: 44390 | AA13: まで | AC13: 2 | AF13: 日間 | AH13: 上申書からの 変更内容※2 | AP13: 変更あり | AX13: 変更なし
A15: 出 発 地 | G15: 杉本キャンパス | P15: 最寄駅又は バス停※1 | V15: ＪＲ | AF15: 線
V16: 杉本町 | AF16: 駅
A17: 帰 着 地 | G17: 自宅 | P17: 最寄駅又は バス停※1 | V17: 大阪メトロ | AF17: 線
V18: 昭和町 | AF18: 駅
B20: 年月日※3 | G20: 用務先名称 | T20: 用務先住所 | AE20: 最寄駅又は バス停※1 | AL20: 宿泊先名称 | AX20: 用務実施内容（報告）
A22: 1 | B22: 44390 | G22: 東京○○センター | T22: 東京都渋谷区○○○○X-XX | AE22: ＪＲ | AK22: 線 | AL22: ○○ビジネスホテル | AX22: 研究課題である「○○」に関する情報収集と研究に関する打ち合わせを行った。
G23: 応接者等 | K23: （ | S23: ） | AE23: 新宿 | AK23: 駅 | AL23: 用務時刻※3 | AQ23: 0.375 | AT23: ～ | AU23: 0.70833333
A24: 2 | AK24: 線
G25: 応接者等 | K25: （ | S25: ） | AK25: 駅 | AL25: 用務時刻※4 | AQ25: ： | AT25: ～ | AU25: ：
A26: 3 | AK26: 線
G27: 応接者等 | K27: （ | S27: ） | AK27: 駅 | AL27: 用務時刻※4 | AQ27: ： | AT27: ～ | AU27: ：
A28: 4 | AK28: 線
G29: 応接者等 | K29: （ | S29: ） | AK29: 駅 | AL29: 用務時刻※4 | AQ29: ： | AT29: ～ | AU29: ：
A30: 5 | AK30: 線
G31: 応接者等 | K31: （ | S31: ） | AK31: 駅 | AL31: 用務時刻※4 | AQ31: ： | AT31: ～ | AU31: ：
A33: 通勤定期区間 ※1 | G33: ① | H33: （自宅最寄り駅） | O33: ～ | P33: （乗換駅） | W33: ( | X33: 大阪メトロ | AD33: ) | AE33: ③ | AM33: ～ | AU33: ( | BB33: ) | BE33: 定期券なし
G34: ② | H34: （乗換駅） | O34: ～ | P34: （勤務地最寄り駅） | W34: ( | X34: ＪＲ | AD34: ) | AE34: ④ | AM34: ～ | AU34: ( | BB34: ) | BC34: ※①が自宅側となるように記入
BC35: 裏面も記入してください。
A37: 教 職 員 | F37: 国内旅行
A40: 財 源 | G40: 財源名称 | O40: 大学運営経費
G41: =IF(OR(O40="基盤研究費",O40="自己負担（精算なし）",O40=""),"",IF(O40="大学運営経費","予算名称",IF(COUNTIF(O40,"*科研費*"),"種目",IF(O40="先方負担","負担種別（全額/一部）",IF(O40="その他","詳細","資金(ﾌﾟﾛｼﾞｪｸﾄ)名称"))))) -> 予算名称 | O41: ○○○○
G42: =+IF(OR(O40="基盤研究費",O40="大学運営経費",O40="自己負担（精算なし）",O40="その他",O40=""),"",IF(O40="先方負担","先方負担先名",IF(COUNTIF(O40,"*科研費*"),"研究代表者名","経費区分（直接/間接）")))
G43: =+IF(OR(O40="基盤研究費",O40="大学運営経費",O40="自己負担（精算なし）",O40="その他",O40=""),"",IF(O40="先方負担","先方負担内容",IF(COUNTIF(O40,"*科研費*"),"所管（ﾌﾟﾛｼﾞｪｸﾄ）名称","ﾌﾟﾛｼﾞｪｸﾄNo.(ｺｰﾄﾞ)")))
G44: =IF(COUNTIF(O40,"*科研費*"),"ﾌﾟﾛｼﾞｪｸﾄNo.(ｺｰﾄﾞ)","")
G45: 備考
A46: 法人カード | I46: 利用あり | Q46: 利用なし
I47: 航空機料金 | Q47: 鉄道料金 | Y47: その他交通費( )
I48: 宿泊料 | Q48: 参加費 | Y48: その他( )
A49: 参 加 費 | G49: 参加費の精算を希望する
A51: 仮 払 精 算 ※5 | I51: 仮払申請額から変更がある（追給あり）
I52: 仮払申請額から変更がある（戻入あり）
A53: 備 考※6
A58: ◆記入に関する注意事項
A60: ※1 最寄駅及び定期区間は「鉄道会社／駅名」又は「バス会社／バス停名」を記入してください。
...

Sheet 旅行命令上申書（国外旅行
A1: 教 職 員 | F1: 国外旅行 | U1: 旅 行 命 令 上 申 書 | AR1: 旅行命令権者 | AX1: 確認欄 | AY1: 課長 | BC1: 課長代理 | BG1: 係長 | BK1: 係員
A6: 公立大学法人大阪 理事長 様 | BE6: 年 月 日
A8: 所 属 | G8: 大阪公立大学工業高等専門学校 | AH8: 旅行者氏名
G9: （役 職） | N9: (選択してください)
B11: 次のとおり旅行命令されるよう上申します。
A13: 旅行期間 | P13: から | AA13: まで | AF13: 日間 | AH13: 用務概要
A15: 出 発 地 | P15: 最寄駅又は バス停※1 | AF15: 線
AF16: 駅
A17: 帰 着 地 | P17: 最寄駅又は バス停※1 | AF17: 線
AF18: 駅
B20: 年月日※2 | G20: 発着地※3 | L20: 利用交通機関※3 | P20: 国名 | T20: 用務先名称及び住所 | AI20: 年月日※2 | AN20: 発着地※3 | AS20: 利用交通機関※3 | AW20: 国名 | BA20: 用務先名称及び住所
G21: 時間 | T21: 宿泊先名称及び住所 | AN21: 時間 | BA21: 宿泊先名称及び住所
A22: 1 | AH22: 4
A26: 2 | AH26: 5
A30: 3 | AH30: 6
A35: 通勤定期区間 ※1 | G35: ① | O35: ～ | W35: ( | AD35: ) | AE35: ③ | AM35: ～ | AU35: ( | BB35: ) | BC35: □ | BE35: 定期券なし
G36: ② | O36: ～ | W36: ( | AD36: ) | AE36: ④ | AM36: ～ | AU36: ( | BB36: ) | BC36: ※①が自宅側となるように記入
BC37: 裏面も記入してください。
A39: 教 職 員 | F39: 国外旅行
A42: 財 源 | G42: 財源名称 | O42: (選択してください)
G43: =IF(OR(O42="基盤研究費",O42="自己負担（精算なし）",O42=""),"",IF(O42="大学運営経費","予算名称",IF(COUNTIF(O42,"*科研費*"),"種目",IF(O42="先方負担","負担種別（全額/一部）",IF(O42="その他","詳細","資金(ﾌﾟﾛｼﾞｪｸﾄ)名称"))))) -> 資金(ﾌﾟﾛｼﾞｪｸﾄ)名称
G44: =+IF(OR(O42="基盤研究費",O42="大学運営経費",O42="自己負担（精算なし）",O42="その他",O42=""),"",IF(O42="先方負担","先方負担先名",IF(COUNTIF(O42,"*科研費*"),"研究代表者名","経費区分（直接/間接）"))) -> 経費区分（直接/間接）
G45: =+IF(OR(O42="基盤研究費",O42="大学運営経費",O42="自己負担（精算なし）",O42="その他",O42=""),"",IF(O42="先方負担","先方負担内容",IF(COUNTIF(O42,"*科研費*"),"所管（ﾌﾟﾛｼﾞｪｸﾄ）名称","ﾌﾟﾛｼﾞｪｸﾄNo.(ｺｰﾄﾞ)"))) -> ﾌﾟﾛｼﾞｪｸﾄNo.(ｺｰﾄﾞ)
G46: =IF(COUNTIF(O42,"*科研費*"),"ﾌﾟﾛｼﾞｪｸﾄNo.(ｺｰﾄﾞ)","")
G47: 備考
A48: 法人カード | G48: □ | I48: 利用予定あり | O48: □ | Q48: 利用予定なし
G49: □ | I49: 航空機料金 | O49: □ | Q49: 鉄道料金 | W49: □ | Y49: その他交通費( )
G50: □ | I50: 宿泊料 | O50: □ | Q50: 参加費 | W50: □ | Y50: その他( )
A51: 参 加 費 | G51: □ | I51: 参加費の精算を希望する
A53: 仮 払 申 請 | G53: □ | I53: 仮払を希望する※4
A55: 国 内 旅 費 | G55: □ | I55: 国内の移動にかかる旅費を請求しない
G56: ※請求しない場合、最寄駅及び通勤定期区間の記入は不要です
A57: 備 考※5
A62: ◆記入に関する注意事項
A64: ※1 最寄駅及び定期区間は「鉄道会社／駅名」又は「バス会社／バス停名」を記入してください。
A65: ※2 旅行期間中の休日に業務を行う場合は、休日振替又は超過勤務の手続きが必要です。
A66: 「休日振替申請書」 又は 「超過勤務（休日）命令／夜間勤務申請簿」を必ず提出してください。ただし、休日における終日移動の場合は不要です。
A67: ※3 発着地・時間及び利用交通機関については、内容がわかる書類を添付することにより記載の省略が可能です。
A68: ※4 仮払いを希望する場合は、原則として、仮払い額（事前算出額）と仮払い精算額（事後の確定額）が同額となるようにしてください。
A69: ※5 国内の移動にかかる旅費を請求する場合で、国内移動に都市間を結ぶ高速バス等（空港連絡バス含む）を利用する際は備考欄に記入してください。
...

Sheet 旅行報告書兼精算依頼書 （国外旅行
A1: 教 職 員 | F1: 国外旅行 | R1: 旅 行 報 告 書 兼 精 算 依 頼 書 | AR1: 旅行命令権者 | AX1: 確認欄 | AY1: 課長 | BC1: 課長代理 | BG1: 係長 | BK1: 係員
A6: 公立大学法人大阪 理事長 様 | BE6: 年 月 日
A8: 所 属 | G8: =IF('[1]旅行命令上申書（国外旅行'!G8:AG8="","",'[1]旅行命令上申書（国外旅行'!G8:AG8) -> 大阪公立大学工業高等専門学校 | AH8: 旅行者氏名 | AN8: =IF('[1]旅行命令上申書（国外旅行'!AN8:BN9="","",'[1]旅行命令上申書（国外旅行'!AN8:BN9)
G9: （役 職） | N9: =IF('[1]旅行命令上申書（国外旅行'!N9:AG9="","",'[1]旅行命令上申書（国外旅行'!N9:AG9)
B11: 次のとおり旅行したことを報告し、旅費の精算を依頼します。
A13: 旅行期間 | G13: =IF('[1]旅行命令上申書（国外旅行'!G13:O14="","",'[1]旅行命令上申書（国外旅行'!G13:O14) | P13: から | R13: =IF('[1]旅行命令上申書（国外旅行'!R13:Z14="","",'[1]旅行命令上申書（国外旅行'!R13:Z14) | AA13: まで | AC13: =IF('[1]旅行命令上申書（国外旅行'!AC13:AE14="","",'[1]旅行命令上申書（国外旅行'!AC13:AE14) | AF13: 日間 | AH13: 上申書からの 変更内容※2 | AP13: 変更あり | AX13: 変更なし
A15: 出 発 地 | G15: =IF('[1]旅行命令上申書（国外旅行'!G15:O16="","",'[1]旅行命令上申書（国外旅行'!G15:O16) | P15: 最寄駅又は バス停※1 | V15: =IF('[1]旅行命令上申書（国外旅行'!V15:AE15="","",'[1]旅行命令上申書（国外旅行'!V15:AE15) | AF15: 線 | AH15: 用務実施内容（報告）
V16: =IF('[1]旅行命令上申書（国外旅行'!V16:AE16="","",'[1]旅行命令上申書（国外旅行'!V16:AE16) | AF16: 駅
A17: 帰 着 地 | G17: =IF('[1]旅行命令上申書（国外旅行'!G17:O18="","",'[1]旅行命令上申書（国外旅行'!G17:O18) | P17: 最寄駅又は バス停※1 | V17: =IF('[1]旅行命令上申書（国外旅行'!V17:AE17="","",'[1]旅行命令上申書（国外旅行'!V17:AE17) | AF17: 線
V18: =IF('[1]旅行命令上申書（国外旅行'!V18:AE18="","",'[1]旅行命令上申書（国外旅行'!V18:AE18) | AF18: 駅
B20: 年月日※3 | G20: 発着地 | L20: 利用交通機関 | P20: 国名 | T20: 用務先名称及び住所 | AI20: 年月日※3 | AN20: 発着地 | AS20: 利用交通機関 | AW20: 国名 | BA20: 用務先名称及び住所
G21: 時間 | T21: 宿泊先名称及び住所 | AN21: 時間 | BA21: 宿泊先名称及び住所
A22: 1 | B22: =IF('[1]旅行命令上申書（国外旅行'!B22:F23="","",'[1]旅行命令上申書（国外旅行'!B22:F23) | G22: =IF('[1]旅行命令上申書（国外旅行'!G22:K22="","",'[1]旅行命令上申書（国外旅行'!G22:K22) | L22: =IF('[1]旅行命令上申書（国外旅行'!L22:O25="","",'[1]旅行命令上申書（国外旅行'!L22:O25) | P22: =IF('[1]旅行命令上申書（国外旅行'!P22:S23="","",'[1]旅行命令上申書（国外旅行'!P22:S23) | T22: =IF('[1]旅行命令上申書（国外旅行'!T22:AG22="","",'[1]旅行命令上申書（国外旅行'!T22:AG22) | AH22: 4 | AI22: =IF('[1]旅行命令上申書（国外旅行'!AI22:AM23="","",'[1]旅行命令上申書（国外旅行'!AI22:AM23) | AN22: =IF('[1]旅行命令上申書（国外旅行'!AN22:AR22="","",'[1]旅行命令上申書（国外旅行'!AN22:AR22) | AS22: =IF('[1]旅行命令上申書（国外旅行'!AS22:AV25="","",'[1]旅行命令上申書（国外旅行'!AS22:AV25) | AW22: =IF('[1]旅行命令上申書（国外旅行'!AW22:AZ23="","",'[1]旅行命令上申書（国外旅行'!AW22:AZ23) | BA22: =IF('[1]旅行命令上申書（国外旅行'!BA22:BN22="","",'[1]旅行命令上申書（国外旅行'!BA22:BN22)
G23: =IF('[1]旅行命令上申書（国外旅行'!G23:K23="","",'[1]旅行命令上申書（国外旅行'!G23:K23) | T23: =IF('[1]旅行命令上申書（国外旅行'!T23:AG23="","",'[1]旅行命令上申書（国外旅行'!T23:AG23) | AN23: =IF('[1]旅行命令上申書（国外旅行'!AN23:AR23="","",'[1]旅行命令上申書（国外旅行'!AN23:AR23) | BA23: =IF('[1]旅行命令上申書（国外旅行'!BA23:BN23="","",'[1]旅行命令上申書（国外旅行'!BA23:BN23)
B24: =IF('[1]旅行命令上申書（国外旅行'!B24:F25="","",'[1]旅行命令上申書（国外旅行'!B24:F25) | G24: =IF('[1]旅行命令上申書（国外旅行'!G24:K24="","",'[1]旅行命令上申書（国外旅行'!G24:K24) | P24: =IF('[1]旅行命令上申書（国外旅行'!P24:S25="","",'[1]旅行命令上申書（国外旅行'!P24:S25) | T24: =IF('[1]旅行命令上申書（国外旅行'!T24:AG24="","",'[1]旅行命令上申書（国外旅行'!T24:AG24) | AI24: =IF('[1]旅行命令上申書（国外旅行'!AI24:AM25="","",'[1]旅行命令上申書（国外旅行'!AI24:AM25) | AN24: =IF('[1]旅行命令上申書（国外旅行'!AN24:AR24="","",'[1]旅行命令上申書（国外旅行'!AN24:AR24) | AW24: =IF('[1]旅行命令上申書（国外旅行'!AW24:AZ25="","",'[1]旅行命令上申書（国外旅行'!AW24:AZ25) | BA24: =IF('[1]旅行命令上申書（国外旅行'!BA24:BN24="","",'[1]旅行命令上申書（国外旅行'!BA24:BN24)
G25: =IF('[1]旅行命令上申書（国外旅行'!G25:K25="","",'[1]旅行命令上申書（国外旅行'!G25:K25) | T25: =IF('[1]旅行命令上申書（国外旅行'!T25:AG25="","",'[1]旅行命令上申書（国外旅行'!T25:AG25) | AN25: =IF('[1]旅行命令上申書（国外旅行'!AN25:AR25="","",'[1]旅行命令上申書（国外旅行'!AN25:AR25) | BA25: =IF('[1]旅行命令上申書（国外旅行'!BA25:BN25="","",'[1]旅行命令上申書（国外旅行'!BA25:BN25)
A26: 2 | B26: =IF('[1]旅行命令上申書（国外旅行'!B26:F27="","",'[1]旅行命令上申書（国外旅行'!B26:F27) | G26: =IF('[1]旅行命令上申書（国外旅行'!G26:K26="","",'[1]旅行命令上申書（国外旅行'!G26:K26) | L26: =IF('[1]旅行命令上申書（国外旅行'!L26:O29="","",'[1]旅行命令上申書（国外旅行'!L26:O29) | P26: =IF('[1]旅行命令上申書（国外旅行'!P26:S27="","",'[1]旅行命令上申書（国外旅行'!P26:S27) | T26: =IF('[1]旅行命令上申書（国外旅行'!T26:AG26="","",'[1]旅行命令上申書（国外旅行'!T26:AG26) | AH26: 5 | AI26: =IF('[1]旅行命令上申書（国外旅行'!AI26:AM27="","",'[1]旅行命令上申書（国外旅行'!AI26:AM27) | AN26: =IF('[1]旅行命令上申書（国外旅行'!AN26:AR26="","",'[1]旅行命令上申書（国外旅行'!AN26:AR26) | AS26: =IF('[1]旅行命令上申書（国外旅行'!AS26:AV29="","",'[1]旅行命令上申書（国外旅行'!AS26:AV29) | AW26: =IF('[1]旅行命令上申書（国外旅行'!AW26:AZ27="","",'[1]旅行命令上申書（国外旅行'!AW26:AZ27) | BA26: =IF('[1]旅行命令上申書（国外旅行'!BA26:BN26="","",'[1]旅行命令上申書（国外旅行'!BA26:BN26)
G27: =IF('[1]旅行命令上申書（国外旅行'!G27:K27="","",'[1]旅行命令上申書（国外旅行'!G27:K27) | T27: =IF('[1]旅行命令上申書（国外旅行'!T27:AG27="","",'[1]旅行命令上申書（国外旅行'!T27:AG27) | AN27: =IF('[1]旅行命令上申書（国外旅行'!AN27:AR27="","",'[1]旅行命令上申書（国外旅行'!AN27:AR27) | BA27: =IF('[1]旅行命令上申書（国外旅行'!BA27:BN27="","",'[1]旅行命令上申書（国外旅行'!BA27:BN27)
B28: =IF('[1]旅行命令上申書（国外旅行'!B28:F29="","",'[1]旅行命令上申書（国外旅行'!B28:F29) | G28: =IF('[1]旅行命令上申書（国外旅行'!G28:K28="","",'[1]旅行命令上申書（国外旅行'!G28:K28) | P28: =IF('[1]旅行命令上申書（国外旅行'!P28:S29="","",'[1]旅行命令上申書（国外旅行'!P28:S29) | T28: =IF('[1]旅行命令上申書（国外旅行'!T28:AG28="","",'[1]旅行命令上申書（国外旅行'!T28:AG28) | AI28: =IF('[1]旅行命令上申書（国外旅行'!AI28:AM29="","",'[1]旅行命令上申書（国外旅行'!AI28:AM29) | AN28: =IF('[1]旅行命令上申書（国外旅行'!AN28:AR28="","",'[1]旅行命令上申書（国外旅行'!AN28:AR28) | AW28: =IF('[1]旅行命令上申書（国外旅行'!AW28:AZ29="","",'[1]旅行命令上申書（国外旅行'!AW28:AZ29) | BA28: =IF('[1]旅行命令上申書（国外旅行'!BA28:BN28="","",'[1]旅行命令上申書（国外旅行'!BA28:BN28)
G29: =IF('[1]旅行命令上申書（国外旅行'!G29:K29="","",'[1]旅行命令上申書（国外旅行'!G29:K29) | T29: =IF('[1]旅行命令上申書（国外旅行'!T29:AG29="","",'[1]旅行命令上申書（国外旅行'!T29:AG29) | AN29: =IF('[1]旅行命令上申書（国外旅行'!AN29:AR29="","",'[1]旅行命令上申書（国外旅行'!AN29:AR29) | BA29: =IF('[1]旅行命令上申書（国外旅行'!BA29:BN29="","",'[1]旅行命令上申書（国外旅行'!BA29:BN29)
A30: 3 | B30: =IF('[1]旅行命令上申書（国外旅行'!B30:F31="","",'[1]旅行命令上申書（国外旅行'!B30:F31) | G30: =IF('[1]旅行命令上申書（国外旅行'!G30:K30="","",'[1]旅行命令上申書（国外旅行'!G30:K30) | L30: =IF('[1]旅行命令上申書（国外旅行'!L30:O33="","",'[1]旅行命令上申書（国外旅行'!L30:O33) | P30: =IF('[1]旅行命令上申書（国外旅行'!P30:S31="","",'[1]旅行命令上申書（国外旅行'!P30:S31) | T30: =IF('[1]旅行命令上申書（国外旅行'!T30:AG30="","",'[1]旅行命令上申書（国外旅行'!T30:AG30) | AH30: 6 | AI30: =IF('[1]旅行命令上申書（国外旅行'!AI30:AM31="","",'[1]旅行命令上申書（国外旅行'!AI30:AM31) | AN30: =IF('[1]旅行命令上申書（国外旅行'!AN30:AR30="","",'[1]旅行命令上申書（国外旅行'!AN30:AR30) | AS30: =IF('[1]旅行命令上申書（国外旅行'!AS30:AV33="","",'[1]旅行命令上申書（国外旅行'!AS30:AV33) | AW30: =IF('[1]旅行命令上申書（国外旅行'!AW30:AZ31="","",'[1]旅行命令上申書（国外旅行'!AW30:AZ31) | BA30: =IF('[1]旅行命令上申書（国外旅行'!BA30:BN30="","",'[1]旅行命令上申書（国外旅行'!BA30:BN30)
G31: =IF('[1]旅行命令上申書（国外旅行'!G31:K31="","",'[1]旅行命令上申書（国外旅行'!G31:K31) | T31: =IF('[1]旅行命令上申書（国外旅行'!T31:AG31="","",'[1]旅行命令上申書（国外旅行'!T31:AG31) | AN31: =IF('[1]旅行命令上申書（国外旅行'!AN31:AR31="","",'[1]旅行命令上申書（国外旅行'!AN31:AR31) | BA31: =IF('[1]旅行命令上申書（国外旅行'!BA31:BN31="","",'[1]旅行命令上申書（国外旅行'!BA31:BN31)
B32: =IF('[1]旅行命令上申書（国外旅行'!B32:F33="","",'[1]旅行命令上申書（国外旅行'!B32:F33) | G32: =IF('[1]旅行命令上申書（国外旅行'!G32:K32="","",'[1]旅行命令上申書（国外旅行'!G32:K32) | P32: =IF('[1]旅行命令上申書（国外旅行'!P32:S33="","",'[1]旅行命令上申書（国外旅行'!P32:S33) | T32: =IF('[1]旅行命令上申書（国外旅行'!T32:AG32="","",'[1]旅行命令上申書（国外旅行'!T32:AG32) | AI32: =IF('[1]旅行命令上申書（国外旅行'!AI32:AM33="","",'[1]旅行命令上申書（国外旅行'!AI32:AM33) | AN32: =IF('[1]旅行命令上申書（国外旅行'!AN32:AR32="","",'[1]旅行命令上申書（国外旅行'!AN32:AR32) | AW32: =IF('[1]旅行命令上申書（国外旅行'!AW32:AZ33="","",'[1]旅行命令上申書（国外旅行'!AW32:AZ33) | BA32: =IF('[1]旅行命令上申書（国外旅行'!BA32:BN32="","",'[1]旅行命令上申書（国外旅行'!BA32:BN32)
G33: =IF('[1]旅行命令上申書（国外旅行'!G33:K33="","",'[1]旅行命令上申書（国外旅行'!G33:K33) | T33: =IF('[1]旅行命令上申書（国外旅行'!T33:AG33="","",'[1]旅行命令上申書（国外旅行'!T33:AG33) | AN33: =IF('[1]旅行命令上申書（国外旅行'!AN33:AR33="","",'[1]旅行命令上申書（国外旅行'!AN33:AR33) | BA33: =IF('[1]旅行命令上申書（国外旅行'!BA33:BN33="","",'[1]旅行命令上申書（国外旅行'!BA33:BN33)
A35: 通勤定期区間 ※1 | G35: ① | H35: =IF('[1]旅行命令上申書（国外旅行'!H35:N35="","",'[1]旅行命令上申書（国外旅行'!H35:N35) | O35: ～ | P35: =IF('[1]旅行命令上申書（国外旅行'!P35:V35="","",'[1]旅行命令上申書（国外旅行'!P35:V35) | W35: ( | X35: =IF('[1]旅行命令上申書（国外旅行'!X35:AC35="","",'[1]旅行命令上申書（国外旅行'!X35:AC35) | AD35: ) | AE35: ③ | AF35: =IF('[1]旅行命令上申書（国外旅行'!AF35:AL35="","",'[1]旅行命令上申書（国外旅行'!AF35:AL35) | AM35: ～ | AN35: =IF('[1]旅行命令上申書（国外旅行'!AN35:AT35="","",'[1]旅行命令上申書（国外旅行'!AN35:AT35) | AU35: ( | AV35: =IF('[1]旅行命令上申書（国外旅行'!AV35:BA35="","",'[1]旅行命令上申書（国外旅行'!AV35:BA35) | BB35: ) | BC35: ='[1]旅行命令上申書（国外旅行'!BC35:BD35 -> □ | BE35: 定期券なし
G36: ② | H36: =IF('[1]旅行命令上申書（国外旅行'!H36:N36="","",'[1]旅行命令上申書（国外旅行'!H36:N36) | O36: ～ | P36: =IF('[1]旅行命令上申書（国外旅行'!P36:V36="","",'[1]旅行命令上申書（国外旅行'!P36:V36) | W36: ( | X36: =IF('[1]旅行命令上申書（国外旅行'!X36:AC36="","",'[1]旅行命令上申書（国外旅行'!X36:AC36) | AD36: ) | AE36: ④ | AF36: =IF('[1]旅行命令上申書（国外旅行'!AF36:AL36="","",'[1]旅行命令上申書（国外旅行'!AF36:AL36) | AM36: ～ | AN36: =IF('[1]旅行命令上申書（国外旅行'!AN36:AT36="","",'[1]旅行命令上申書（国外旅行'!AN36:AT36) | AU36: ( | AV36: =IF('[1]旅行命令上申書（国外旅行'!AV36:BA36="","",'[1]旅行命令上申書（国外旅行'!AV36:BA36) | BB36: ) | BC36: ※①が自宅側となるように記入
BC37: 裏面も記入してください。
A39: 教 職 員 | F39: 国外旅行
A42: 財 源 | G42: 財源名称 | O42: =IF('[1]旅行命令上申書（国外旅行'!O42:AG42="","",'[1]旅行命令上申書（国外旅行'!O42:AG42) -> (選択してください) | AI42: 参加費の精算を希望する場合、参加費に食事代が含まれますか。
G43: =IF(OR(O42="基盤研究費",O42="自己負担（精算なし）",O42=""),"",IF(O42="大学運営経費","予算名称",IF(COUNTIF(O42,"*科研費*"),"種目",IF(O42="先方負担","負担種別（全額/一部）",IF(O42="その他","詳細","資金(ﾌﾟﾛｼﾞｪｸﾄ)名称"))))) -> 資金(ﾌﾟﾛｼﾞｪｸﾄ)名称 | O43: =IF('[1]旅行命令上申書（国外旅行'!O43:AG43="","",'[1]旅行命令上申書（国外旅行'!O43:AG43) | AJ43: 国外の学会等に現地参加し、学会等の参加費に食事代（朝食・昼食・夕食）が含まれる場合は、その種別及び食事の回数をご記入ください。 朝食、昼食、夕食が茶菓子等で１食分の食事相当ではない場合は、「軽食｣欄に回数を記入して下さい。 ※プログラム等の食事有無・内容が確認できる資料を添付してください。 ※「プログラムに記載の食事回数合計」＝「以下記載の回数合計（朝食・昼食・夕食・軽食」であることを確認してください。
G44: =+IF(OR(O42="基盤研究費",O42="大学運営経費",O42="自己負担（精算なし）",O42="その他",O42=""),"",IF(O42="先方負担","先方負担先名",IF(COUNTIF(O42,"*科研費*"),"研究代表者名","経費区分（直接/間接）"))) -> 経費区分（直接/間接） | O44: =IF('[1]旅行命令上申書（国外旅行'!O44:AG44="","",'[1]旅行命令上申書（国外旅行'!O44:AG44)
G45: =+IF(OR(O42="基盤研究費",O42="大学運営経費",O42="自己負担（精算なし）",O42="その他",O42=""),"",IF(O42="先方負担","先方負担内容",IF(COUNTIF(O42,"*科研費*"),"所管（ﾌﾟﾛｼﾞｪｸﾄ）名称","ﾌﾟﾛｼﾞｪｸﾄNo.(ｺｰﾄﾞ)"))) -> ﾌﾟﾛｼﾞｪｸﾄNo.(ｺｰﾄﾞ) | O45: =IF('[1]旅行命令上申書（国外旅行'!O45:AG45="","",'[1]旅行命令上申書（国外旅行'!O45:AG45)
G46: =IF(COUNTIF(O42,"*科研費*"),"ﾌﾟﾛｼﾞｪｸﾄNo.(ｺｰﾄﾞ)","") | O46: =IF('[1]旅行命令上申書（国外旅行'!O46:AG46="","",'[1]旅行命令上申書（国外旅行'!O46:AG46)
G47: 備考 | O47: =IF('[1]旅行命令上申書（国外旅行'!O47:AG47="","",'[1]旅行命令上申書（国外旅行'!O47:AG47)
A48: 法人カード | G48: ='[1]旅行命令上申書（国外旅行'!G48:H48 -> □ | I48: 利用あり | O48: ='[1]旅行命令上申書（国外旅行'!O48:P48 -> □ | Q48: 利用なし
G49: ='[1]旅行命令上申書（国外旅行'!G49:H49 -> □ | I49: 航空機料金 | O49: ='[1]旅行命令上申書（国外旅行'!O49:P49 -> □ | Q49: 鉄道料金 | W49: ='[1]旅行命令上申書（国外旅行'!W49:X49 -> □ | Y49: その他交通費( )
G50: ='[1]旅行命令上申書（国外旅行'!G50:H50 -> □ | I50: 宿泊料 | O50: ='[1]旅行命令上申書（国外旅行'!O50:P50 -> □ | Q50: 参加費 | W50: ='[1]旅行命令上申書（国外旅行'!W50:X50 -> □ | Y50: その他( ) | AJ50: □ | AL50: 参加費に食事代が含まれる
A51: 参 加 費 | G51: ='[1]旅行命令上申書（国外旅行'!G51:H52 -> □ | I51: 参加費の精算を希望する | AK51: <食事の内訳>
AK52: □ | AM52: 朝食 | AR52: 回
A53: 仮 払 精 算 ※4 | G53: □ | I53: 仮払申請額から変更がある（追給あり） | AK53: □ | AM53: 昼食 | AR53: 回
...

Sheet 記入例 （国外旅行
A1: 教 職 員 | F1: 国外旅行 | R1: 旅行報告書兼精算依頼書（記入例） | AR1: 旅行命令権者 | AX1: 確認欄 | AY1: 課長 | BC1: 課長代理 | BG1: 係長 | BK1: 係員
A6: 公立大学法人大阪 理事長 様 | BE6: 年 月 日
A8: 所 属 | AH8: 旅行者氏名
G9: （役 職）
B11: 次のとおり旅行したことを報告し、旅費の精算を依頼します。
A13: 旅行期間 | G13: 43924 | P13: から | R13: 43928 | AA13: まで | AC13: 5 | AF13: 日間 | AH13: 上申書からの 変更内容※2 | AP13: 変更あり | AX13: 変更なし
A15: 出 発 地 | G15: 杉本キャンパス | P15: 最寄駅又は バス停※1 | V15: ＪＲ | AF15: 線 | AH15: 用務実施内容（報告） | AN15: 4/4に○○にて開催される学会「○○」に出席し、研究発表及び参加する研究者達と情報交換を行った。学会への出席を通じて国外の研究者達と交流する機会が得られた。これらのことは今後の自らの研究及び教育に生かし、より発展させることができるものと期待される。
V16: 杉本町 | AF16: 駅
A17: 帰 着 地 | G17: 自宅 | P17: 最寄駅又は バス停※1 | V17: 大阪メトロ | AF17: 線
V18: 昭和町 | AF18: 駅
B20: 年月日※3 | G20: 発着地 | L20: 利用交通機関 | P20: 国名 | T20: 用務先名称及び住所 | AI20: 年月日※3 | AN20: 発着地 | AS20: 利用交通機関 | AW20: 国名 | BA20: 用務先名称及び住所
G21: 時間 | T21: 宿泊先名称及び住所 | AN21: 時間 | BA21: 宿泊先名称及び住所
A22: 1 | B22: 43924 | G22: 伊丹空港 | L22: JL3006 | P22: 日本 | T22: 移動日 | AH22: 4 | AI22: 43927 | AN22: JFK空港 | AS22: JL0005 | AW22: アメリカ | BA22: 移動日
G23: 0.60763889 | AN23: 0.53472222
B24: 43924 | G24: 成田空港 | P24: 日本 | AI24: 43928 | AN24: 成田空港 | AW24: 日本
G25: 0.66319444 | AN25: 0.71527778
A26: 2 | B26: 43924 | G26: 成田空港 | L26: JL0004 | P26: 日本 | T26: 移動日 | AH26: 5 | AI26: 43928 | AN26: 成田空港 | AS26: JL0137 | AW26: 日本 | BA26: 移動日
G27: 0.8125 | AN27: 0.79166667
B28: 43924 | G28: JFK空港 | P28: アメリカ | T28: ●●ホテル | AI28: 43928 | AN28: 伊丹空港 | AW28: 日本
G29: 0.76736111 | T29: （TEL：***-****-****） | AN29: 0.84722222
A30: 3 | B30: 43925 | L30: - | P30: アメリカ | T30: 〇〇学会 | AH30: 6
T31: 会場：××コンベンションセンター
B32: 43926 | P32: アメリカ | T32: ●●ホテル
T33: （TEL：***-****-****）
A35: 通勤定期区間 ※1 | G35: ① | H35: （自宅最寄り駅） | O35: ～ | P35: （乗換駅） | W35: ( | X35: 大阪メトロ | AD35: ) | AE35: ③ | AM35: ～ | AU35: ( | BB35: ) | BE35: 定期券なし
G36: ② | H36: （乗換駅） | O36: ～ | P36: （勤務地最寄り駅） | W36: ( | X36: ＪＲ | AD36: ) | AE36: ④ | AM36: ～ | AU36: ( | BB36: ) | BC36: ※①が自宅側となるように記入
BC37: 裏面も記入してください。
A39: 教 職 員 | F39: 国外旅行
A42: 財 源 | G42: 財源名称 | O42: 科研費（代表者） | AI42: 参加費の精算を希望する場合、参加費に食事代が含まれますか。
G43: =IF(OR(O42="基盤研究費",O42="自己負担（精算なし）",O42=""),"",IF(O42="大学運営経費","予算名称",IF(COUNTIF(O42,"*科研費*"),"種目",IF(O42="先方負担","負担種別（全額/一部）",IF(O42="その他","詳細","資金(ﾌﾟﾛｼﾞｪｸﾄ)名称"))))) -> 種目 | O43: 基盤Ｃ | AJ43: 国外の学会等に現地参加し、学会等の参加費に食事代（朝食・昼食・夕食）が含まれる場合は、その種別及び食事の回数をご記入ください。 朝食、昼食、夕食が茶菓子等で１食分の食事相当ではない場合は、「軽食｣欄に回数を記入して下さい。 ※プログラム等の食事有無・内容が確認できる資料を添付してください。 ※「プログラムに記載の食事回数合計」＝「以下記載の回数合計（朝食・昼食・夕食・軽食」であることを確認してください。
G44: =+IF(OR(O42="基盤研究費",O42="大学運営経費",O42="自己負担（精算なし）",O42="その他",O42=""),"",IF(O42="先方負担","先方負担先名",IF(COUNTIF(O42,"*科研費*"),"研究代表者名","経費区分（直接/間接）"))) -> 研究代表者名 | O44: ○○ ○○
G45: =+IF(OR(O42="基盤研究費",O42="大学運営経費",O42="自己負担（精算なし）",O42="その他",O42=""),"",IF(O42="先方負担","先方負担内容",IF(COUNTIF(O42,"*科研費*"),"所管（ﾌﾟﾛｼﾞｪｸﾄ）名称","ﾌﾟﾛｼﾞｪｸﾄNo.(ｺｰﾄﾞ)"))) -> 所管（ﾌﾟﾛｼﾞｪｸﾄ）名称 | O45: ○○○○○○
G46: =IF(COUNTIF(O42,"*科研費*"),"ﾌﾟﾛｼﾞｪｸﾄNo.(ｺｰﾄﾞ)","") -> ﾌﾟﾛｼﾞｪｸﾄNo.(ｺｰﾄﾞ) | O46: KXXKXXXXX
G47: 備考
A48: 法人カード | I48: 利用あり | Q48: 利用なし
I49: 航空機料金 | Q49: 鉄道料金 | Y49: その他交通費( )
I50: 宿泊料 | Q50: 参加費 | Y50: その他( ) | AL50: 参加費に食事代が含まれる
A51: 参 加 費 | G51: 参加費の精算を希望する | AK51: <食事の内訳>
AM52: 朝食 | AR52: 回
A53: 仮 払 精 算 ※4 | I53: 仮払申請額から変更がある（追給あり） | AM53: 昼食 | AR53: 回
...
